Traceback (most recent call last):
  File "/Users/johnlockwood/source/JohnLockwood/johnlockwood.github.io/.venv/lib/python3.11/site-packages/jupyter_cache/executors/utils.py", line 58, in single_nb_execution
    executenb(
  File "/Users/johnlockwood/source/JohnLockwood/johnlockwood.github.io/.venv/lib/python3.11/site-packages/nbclient/client.py", line 1305, in execute
    return NotebookClient(nb=nb, resources=resources, km=km, **kwargs).execute()
           ^^^^^^^^^^^^^^^^^^^^^^^^^^^^^^^^^^^^^^^^^^^^^^^^^^^^^^^^^^^^^^^^^^^^^
  File "/Users/johnlockwood/source/JohnLockwood/johnlockwood.github.io/.venv/lib/python3.11/site-packages/jupyter_core/utils/__init__.py", line 173, in wrapped
    return loop.run_until_complete(inner)
           ^^^^^^^^^^^^^^^^^^^^^^^^^^^^^^
  File "/Library/Frameworks/Python.framework/Versions/3.11/lib/python3.11/asyncio/base_events.py", line 653, in run_until_complete
    return future.result()
           ^^^^^^^^^^^^^^^
  File "/Users/johnlockwood/source/JohnLockwood/johnlockwood.github.io/.venv/lib/python3.11/site-packages/nbclient/client.py", line 705, in async_execute
    await self.async_execute_cell(
  File "/Users/johnlockwood/source/JohnLockwood/johnlockwood.github.io/.venv/lib/python3.11/site-packages/nbclient/client.py", line 1058, in async_execute_cell
    await self._check_raise_for_error(cell, cell_index, exec_reply)
  File "/Users/johnlockwood/source/JohnLockwood/johnlockwood.github.io/.venv/lib/python3.11/site-packages/nbclient/client.py", line 914, in _check_raise_for_error
    raise CellExecutionError.from_cell_and_msg(cell, exec_reply_content)
nbclient.exceptions.CellExecutionError: An error occurred while executing the following cell:
------------------
f
print(sin(pi/3))
print(sin(pi/3) * 5)
------------------


[0;31m---------------------------------------------------------------------------[0m
[0;31mNameError[0m                                 Traceback (most recent call last)
Cell [0;32mIn[8], line 2[0m
[1;32m      1[0m f
[0;32m----> 2[0m [38;5;28mprint[39m([43msin[49m(pi[38;5;241m/[39m[38;5;241m3[39m))
[1;32m      3[0m [38;5;28mprint[39m(sin(pi[38;5;241m/[39m[38;5;241m3[39m) [38;5;241m*[39m [38;5;241m5[39m)

[0;31mNameError[0m: name 'sin' is not defined

